Traceback:
my_test -> test_inner -> inner
Exception:
TypeError: message_error
